<?xml version="1.0"?>
<robot xmlns:xacro="http://www.ros.org/wiki/xacro">

  <xacro:include filename="inertial_macros.xacro"/>

  <material name="white">
    <color rgba="1 1 1 1"/>
  </material>

  <material name="orange">
    <color rgba="1 0.3 0.1 1"/>
  </material>

  <material name="blue">
    <color rgba="0.2 0.2 1 1"/>
  </material>

  <material name="black">
    <color rgba="0 0 0 1"/>
  </material>

  <!-- BASE LINK -->
  <link name="base_link">

  </link>

  <!-- Path to mesh -->
  <xacro:property name="mesh_path" value="srs/my_bot/description/girello.stl" />

  <!-- CHASSIS LINK -->
  <joint name="chassis_joint" type="fixed">
    <parent link="base_link"/>
    <child link="chassis"/>
    <origin xyz="-0.1 0 0"/>
  </joint>

  <link name="chassis">
    <visual>
      <origin xyz="0.1 0 0.115" rpy="${pi/2} 0 -${pi/2}"/>
      <geometry>
        <mesh filename="${mesh_path}" scale="0.01 0.01 0.01"/>
      </geometry>
      <material name="white"/>
    </visual>
    <collision>
      <origin xyz="0.4 0 0.115"/>
      <geometry>
        <box size="0.7 0.46 0.15"/>
      </geometry>
    </collision>
    <xacro:inertial_box mass="0.5" x="0.5" y="0.7" z="0.15">
      <origin xyz="0.15 0 0.115" rpy="0 0 0"/>
    </xacro:inertial_box>
  </link>

  <gazebo reference="chassis">
    <material>Gazebo/White</material>
  </gazebo>

  <!-- LEFT WHEEL LINK -->
  <joint name="left_wheel_joint" type="continuous">
    <parent link="base_link"/>
    <child link="left_wheel"/>
    <origin xyz="0 0.307 0" rpy="-${pi/2} 0 0"/>
    <axis xyz="0 0 1"/>
  </joint>

  <link name="left_wheel">
    <visual>
      <geometry>
        <cylinder radius="0.125" length="0.04"/>
      </geometry>
      <material name="blue"/>
    </visual>
    <collision>
      <geometry>
        <cylinder radius="0.125" length="0.04"/>
      </geometry>
    </collision>
    <xacro:inertial_cylinder mass="0.1" length="0.04" radius="0.05">
      <origin xyz="0 0 0" rpy="0 0 0"/>
    </xacro:inertial_cylinder>
  </link>

  <gazebo reference="left_wheel">
    <material>Gazebo/Blue</material>
  </gazebo>

  <!-- RIGHT WHEEL LINK -->
  <joint name="right_wheel_joint" type="continuous">
    <parent link="base_link"/>
    <child link="right_wheel"/>
    <origin xyz="0 -0.307 0" rpy="${pi/2} 0 0"/>
    <axis xyz="0 0 -1"/>
  </joint>

  <link name="right_wheel">
    <visual>
      <geometry>
        <cylinder radius="0.125" length="0.04"/>
      </geometry>
      <material name="blue"/>
    </visual>
    <collision>
      <geometry>
        <cylinder radius="0.125" length="0.04"/>
      </geometry>
    </collision>
    <xacro:inertial_cylinder mass="0.1" length="0.04" radius="0.05">
      <origin xyz="0 0 0" rpy="0 0 0"/>
    </xacro:inertial_cylinder>
  </link>

  <gazebo reference="right_wheel">
    <material>Gazebo/Blue</material>
  </gazebo>

  <!-- LEFT FORK LINK -->
  <joint name="left_fork_joint" type="continuous">
    <parent link="chassis"/>
    <child link="left_fork"/>
    <origin xyz="0.73 0.25 0.03" rpy="0 0 0"/>
    <axis xyz="0 0 1"/>
  </joint>

  <link name="left_fork">
    <visual>
      <geometry>
        <cylinder radius="0.015" length="0.04"/>
      </geometry>
      <material name="blue"/>
    </visual>
<!--     <collision>
      <geometry>
        <cylinder radius="0.015" length="0.04"/>
      </geometry>
    </collision> -->
    <xacro:inertial_cylinder mass="0.1" length="0.04" radius="0.015">
      <origin xyz="0 0 0" rpy="0 0 0"/>
    </xacro:inertial_cylinder>
  </link>

  <gazebo reference="left_fork">
    <material>Gazebo/Blue</material>
    <mu1 value="0.01"/>
    <mu2 value="0.01"/>
  </gazebo>

  <!-- LEFT CASTER WHEEL LINK -->
    <joint name="left_cast_wheel_joint" type="continuous">
    <parent link="left_fork"/>
    <child link="left_caster_wheel"/>
    <origin xyz="-0.04 0 -0.0875" rpy="${pi/2} 0 0"/>
    <axis xyz="0 0 -1"/>
  </joint>

   <link name="left_caster_wheel">
    <visual>
      <geometry>
        <cylinder radius="0.0675" length="0.03"/>
      </geometry>
      <material name="blue"/>
    </visual>
    <collision>
      <geometry>
        <cylinder radius="0.0675" length="0.03"/>
      </geometry>
    </collision>
    <xacro:inertial_cylinder mass="0.1" length="0.03" radius="0.0675">
      <origin xyz="0 0 0" rpy="0 0 0"/>
    </xacro:inertial_cylinder>
  </link>

  <gazebo reference="left_caster_wheel">
    <material>Gazebo/Blue</material>
  </gazebo>

    <!-- RIGHT FORK LINK -->
  <joint name="right_fork_joint" type="continuous">
    <parent link="chassis"/>
    <child link="right_fork"/>
    <origin xyz="0.73 -0.25 0.03" rpy="0 0 0"/>
    <axis xyz="0 0 1"/>
  </joint>

  <link name="right_fork">
        <visual>
      <geometry>
        <cylinder radius="0.015" length="0.04"/>
      </geometry>
      <material name="blue"/>
    </visual>
<!--     <collision>
      <geometry>
        <cylinder radius="0.015" length="0.04"/>
      </geometry>
    </collision> -->
    <xacro:inertial_cylinder mass="0.1" length="0.04" radius="0.015">
      <origin xyz="0 0 0" rpy="0 0 0"/>
    </xacro:inertial_cylinder>
  </link>

  <gazebo reference="right_fork">
    <material>Gazebo/Blue</material>
    <mu1 value="0.01"/>
    <mu2 value="0.01"/>
  </gazebo>

  <!-- RIGHT CASTER WHEEL LINK -->
    <joint name="right_cast_wheel_joint" type="continuous">
    <parent link="right_fork"/>
    <child link="right_caster_wheel"/>
    <origin xyz="-0.04 0 -0.0875" rpy="${pi/2} 0 0"/>
    <axis xyz="0 0 -1"/>
  </joint>

   <link name="right_caster_wheel">
    <visual>
      <geometry>
        <cylinder radius="0.0675" length="0.03"/>
      </geometry>
      <material name="blue"/>
    </visual>
    <collision>
      <geometry>
        <cylinder radius="0.0675" length="0.03"/>
      </geometry>
    </collision>
    <xacro:inertial_cylinder mass="0.1" length="0.03" radius="0.0675">
      <origin xyz="0 0 0" rpy="0 0 0"/>
    </xacro:inertial_cylinder>
  </link>

  <gazebo reference="right_caster_wheel">
    <material>Gazebo/Blue</material>
  </gazebo>

<!--   <gazebo reference="caster_wheel">
    <material>Gazebo/Black</material>
    <mu1 value="0.001"/>
    <mu2 value="0.001"/>
  </gazebo> -->

</robot>